Workbook

Sheet Calculator
A1: 🕌 Zam Zam Travel Package Calculator
A3: 📅 ข้อมูลทริป
A4: วันที่เดินทาง
A5: วันที่กลับ
A6: จำนวนวัน | B6: 7
A7: จำนวนคืน | B7: 6
A8: จำนวนผู้เดินทาง | B8: 2
A10: รายการ | B10: ตัวเลือก | C10: จำนวน | D10: ราคา/หน่วย | E10: รวม (บาท) | F10: หมายเหตุ
A11: ✈️ ตั๋วเครื่องบิน | B11: Gulf Air | C11: 2 | D11: =VLOOKUP(B11,'Price List'!A5:B10,2,FALSE()) -> 14000 | E11: =C11*D11 -> 28000 | F11: ไป-กลับ
A12: 📋 วีซ่า | B12: อุมเราะห์ | C12: 2 | D12: =VLOOKUP(B12,'Price List'!A14:B17,2,FALSE()) -> 6500 | E12: =C12*D12 -> 13000
A13: 🏨 รร. มักกะห์ | B13: 3 ดาว | C13: 3 | D13: =VLOOKUP(B13,'Price List'!A22:E25,2,FALSE()) -> 1500 | E13: =C13*D13 -> 4500 | F13: คืน
A14: 🏨 รร. มาดีนะห์ | B14: 3 ดาว | C14: 3 | D14: =VLOOKUP(B14,'Price List'!A22:E25,3,FALSE()) -> 1200 | E14: =C14*D14 -> 3600 | F14: คืน
A15: 🏨 รร. เจดดะห์ | B15: 4 ดาว | C15: 0 | D15: =VLOOKUP(B15,'Price List'!A22:E25,4,FALSE()) -> 2200 | E15: =C15*D15 -> 0 | F15: คืน
A16: 🏨 รร. ริยาด | B16: 4 ดาว | C16: 0 | D16: =VLOOKUP(B16,'Price List'!A22:E25,5,FALSE()) -> 2500 | E16: =C16*D16 -> 0 | F16: คืน
A17: รวมค่าโรงแรม | E17: =SUM(E13:E16) -> 8100
A18: 🚐 รถ | B18: รถตู้ VIP | C18: 7 | D18: =VLOOKUP(B18,'Price List'!A30:B34,2,FALSE()) -> 3500 | E18: =C18*D18 -> 24500 | F18: วัน
A19: 👨‍🏫 ไกด์ | B19: ฟูลทริป | C19: 1 | D19: =VLOOKUP(B19,'Price List'!A38:B42,2,FALSE()) -> 20000 | E19: =C19*D19 -> 20000 | F19: วัน
A20: 🍽️ อาหาร | B20: ฟูลบอร์ด 3 มื้อ | C20: 7 | D20: =VLOOKUP(B20,'Price List'!A46:B49,2,FALSE()) -> 800 | E20: =C20*D20 -> 5600 | F20: วัน
A21: ⭐ บริการเสริม
A22: - Ziarah Makkah | B22: ต้องการ | C22: 1 | D22: ='Price List'!B53 -> 1500 | E22: =IF(B22="ต้องการ",C22*D22,0) -> 1500
A23: - Ziarah Madinah | B23: ต้องการ | C23: 1 | D23: ='Price List'!B54 -> 1500 | E23: =IF(B23="ต้องการ",C23*D23,0) -> 1500
A24: - Ziarah Taif | B24: ไม่ต้องการ | C24: 0 | D24: ='Price List'!B55 -> 2500 | E24: =IF(B24="ต้องการ",C24*D24,0) -> 0
A25: - Al-Ula Tour | B25: ไม่ต้องการ | C25: 0 | D25: ='Price List'!B56 -> 8000 | E25: =IF(B25="ต้องการ",C25*D25,0) -> 0
A26: - Red Sea (ทะเลแดง) | B26: ไม่ต้องการ | C26: 0 | D26: ='Price List'!B57 -> 5000 | E26: =IF(B26="ต้องการ",C26*D26,0) -> 0
A27: - Jeddah City Tour | B27: ไม่ต้องการ | C27: 0 | D27: ='Price List'!B58 -> 2000 | E27: =IF(B27="ต้องการ",C27*D27,0) -> 0
A28: รวมบริการเสริม | E28: =SUM(E22:E27) -> 3000
A30: 💰 รวมต้นทุน (ต่อคน) | E30: =E11+E12+E17+E18+E19+E20+E28/B8 -> 100700
A31: 💰💰 รวมต้นทุน (ทั้งกลุ่ม) | E31: =E30*B8 -> 201400
A33: 📊 คำนวณราคาขาย (ส่วนนี้ลูกค้าไม่เห็น)
A34: อัตรากำไร (%) | B34: 10 | C34: %
A35: ปัดเศษราคาขาย | B35: 100 | C35: บาท (100, 500, 1000)
A36: กำไรต่อคน | B36: =E30*(B34/100) -> 10070 | C36: บาท
A37: ราคาขายต่อคน (ก่อนปัด) | B37: =E30*(1+B34/100) -> 110770 | C37: บาท
A38: 💵 ราคาขายต่อคน (ปัดแล้ว) | B38: =CEILING(E30*(1+B34/100),B35) -> 110800 | C38: บาท
A39: 💵💵 ราคาขายทั้งกลุ่ม | B39: =B38*B8 -> 221600 | C39: บาท
A40: กำไรจริงทั้งกลุ่ม | B40: =B39-E31 -> 20200 | C40: บาท

Sheet Price List
A3: ✈️ สายการบิน
A4: สายการบิน | B4: ราคา (บาท)
A5: Saudia | B5: 15000
A6: Qatar Airways | B6: 18000
A7: Gulf Air | B7: 14000
A8: Bahrain Air | B8: 13000
A9: Emirates | B9: 20000
A10: Budget (ถูกสุด) | B10: 12000
A12: 📋 วีซ่า
A13: ประเภท | B13: ราคา (บาท)
A14: อุมเราะห์ | B14: 6500
A15: ท่องเที่ยว | B15: 4500
A16: ทำงาน | B16: 5000
A17: ธุรกิจ | B17: 4500
A20: 🏨 โรงแรม (ราคาต่อคืน)
A21: ระดับ | B21: มักกะห์ | C21: มาดีนะห์ | D21: เจดดะห์ | E21: ริยาด
A22: 2 ดาว | B22: 800 | C22: 700 | D22: 900 | E22: 1000
A23: 3 ดาว | B23: 1500 | C23: 1200 | D23: 1400 | E23: 1600
A24: 4 ดาว | B24: 2500 | C24: 2000 | D24: 2200 | E24: 2500
A25: 5 ดาว | B25: 5000 | C25: 4000 | D25: 4500 | E25: 5500
A28: 🚐 รถ (ราคาต่อวัน)
A29: ประเภท | B29: ราคา (บาท)
A30: รถตู้ VIP | B30: 3500
A31: รถตู้ธรรมดา | B31: 2500
A32: รถมินิบัส | B32: 4500
A33: รถบัส | B33: 6000
A34: รถเก๋ง | B34: 2000
A37: 👨‍🏫 ไกด์ (ราคาต่อวัน)
A38: ฟูลทริป | B38: 20000
A39: เฉพาะมักกะห์ | B39: 2000
A40: เฉพาะมาดีนะห์ | B40: 2000
A41: เฉพาะเจดดะห์ | B41: 2000
A42: ไม่ต้องการ | B42: 0
A44: 🍽️ อาหาร (ราคาต่อวัน)
A45: ตัวเลือก | B45: ราคา (บาท)
A46: ฟูลบอร์ด 3 มื้อ | B46: 800
A47: 2 มื้อ (เช้า-เย็น) | B47: 600
A48: 1 มื้อ (เช้า) | B48: 300
A49: ซื้อเอง (ไม่รวม) | B49: 0
A51: ⭐ บริการเสริม
...

Sheet Summary
B2: 🕌 ใบเสนอราคาแพคเกจท่องเที่ยว
B3: Zam Zam Travel Package
B5: บริษัท ............................ จำกัด
B6: โทร: ................ | Line: ................
B8: 📅 รายละเอียดการเดินทาง
B9: วันที่เดินทาง | C9: =Calculator!B4
B10: วันที่กลับ | C10: =Calculator!B5
B11: ระยะเวลา | C11: =Calculator!B6&" วัน "&Calculator!B7&" คืน" -> 7 วัน 6 คืน
B12: จำนวนผู้เดินทาง | C12: =Calculator!B8&" ท่าน" -> 2 ท่าน
B14: ✨ รายการที่รวมในแพคเกจ
B15: ✈️ ตั๋วเครื่องบิน | C15: =Calculator!B11&" (ไป-กลับ)" -> Gulf Air (ไป-กลับ)
B16: 📋 วีซ่า | C16: ="วีซ่า "&Calculator!B12 -> วีซ่า อุมเราะห์
B17: 🏨 ที่พัก | C17: =IF(Calculator!C13>0,Calculator!B13&" "&Calculator!C13&" คืน (มักกะห์)","")&IF(AND(Calculator!C13>0,Calculator!C14>0),", ","")&IF(Calculator!C14>0,Calculator!B14&" "&Calculator!C14&" คืน (มาดีนะห์)","")&IF(AND(OR(Calculator!C13>0,Calculator!C14>0),Calculator!C15>0),", ","")&IF(Calculator!C15>0,Calculator!B15&" "&Calculator!C15&" คืน (เจดดะห์)","")&IF(AND(OR(Calculator!C13>0,Calculator!C14>0,Calculator!C15>0),Calculator!C16>0),", ","")&IF(Calculator!C16>0,Calculator!B16&" "&Calculator!C16&" คืน (ริยาด)","") -> 3 ดาว 3 คืน (มักกะห์), 3 ดาว 3 คืน (มาดีนะห์)
B18: 🚐 รถรับส่ง | C18: =Calculator!B18&" ("&Calculator!C18&" วัน)" -> รถตู้ VIP (7 วัน)
B19: 👨‍🏫 ไกด์ | C19: =IF(Calculator!B19="ไม่ต้องการ","ไม่รวม",Calculator!B19&" ("&Calculator!C19&" วัน)") -> ฟูลทริป (1 วัน)
B20: 🍽️ อาหาร | C20: =IF(Calculator!B20="ซื้อเอง (ไม่รวม)","ไม่รวม",Calculator!B20&" ("&Calculator!C20&" วัน)") -> ฟูลบอร์ด 3 มื้อ (7 วัน)
B22: ⭐ บริการเสริม (Ziarah & Tours)
B23: โปรแกรมพิเศษ | C23: =IF(Calculator!B22="ต้องการ","• Ziarah Makkah","")&IF(Calculator!B23="ต้องการ",CHAR(10)&"• Ziarah Madinah","")&IF(Calculator!B24="ต้องการ",CHAR(10)&"• Ziarah Taif","")&IF(Calculator!B25="ต้องการ",CHAR(10)&"• Al-Ula Tour","")&IF(Calculator!B26="ต้องการ",CHAR(10)&"• Red Sea (ทะเลแดง)","")&IF(Calculator!B27="ต้องการ",CHAR(10)&"• Jeddah City Tour","") -> • Ziarah Makkah • Ziarah Madinah
B26: 💰 ราคาแพคเกจ
B28: 💵 ราคาแพคเกจต่อท่าน | D28: =Calculator!B38 -> 110800
B29: 💵💵 ราคารวมทั้งกลุ่ม | D29: =Calculator!B39 -> 221600
B31: 📝 หมายเหตุ
B32: • ราคานี้ยังไม่รวมค่าใช้จ่ายส่วนตัว
B33: • ราคาอาจเปลี่ยนแปลงตามฤดูกาลและอัตราแลกเปลี่ยน
B34: • กรุณาสำรองที่นั่งล่วงหน้าอย่างน้อย 30 วัน
B35: • ชำระมัดจำ 30% เพื่อยืนยันการจอง
B37: ขอบคุณที่ไว้วางใจใช้บริการ 🤲
